Defaulting to user installation because normal site-packages is not writeable
Requirement already satisfied: discord.py in ./.local/lib/python3.9/site-packages (2.1.0)
Requirement already satisfied: aiohttp<4,>=3.7.4 in ./.local/lib/python3.9/site-packages (from discord.py) (3.8.3)
Requirement already satisfied: multidict<7.0,>=4.5 in ./.local/lib/python3.9/site-packages (from aiohttp<4,>=3.7.4->discord.py) (6.0.4)
Requirement already satisfied: aiosignal>=1.1.2 in ./.local/lib/python3.9/site-packages (from aiohttp<4,>=3.7.4->discord.py) (1.3.1)
Requirement already satisfied: charset-normalizer<3.0,>=2.0 in ./.local/lib/python3.9/site-packages (from aiohttp<4,>=3.7.4->discord.py) (2.1.1)
Requirement already satisfied: yarl<2.0,>=1.0 in ./.local/lib/python3.9/site-packages (from aiohttp<4,>=3.7.4->discord.py) (1.8.2)
Requirement already satisfied: frozenlist>=1.1.1 in ./.local/lib/python3.9/site-packages (from aiohttp<4,>=3.7.4->discord.py) (1.3.3)
Requirement already satisfied: attrs>=17.3.0 in ./.local/lib/python3.9/site-packages (from aiohttp<4,>=3.7.4->discord.py) (22.2.0)
Requirement already satisfied: async-timeout<5.0,>=4.0.0a3 in ./.local/lib/python3.9/site-packages (from aiohttp<4,>=3.7.4->discord.py) (4.0.2)
Requirement already satisfied: idna>=2.0 in /usr/lib/python3/dist-packages (from yarl<2.0,>=1.0->aiohttp<4,>=3.7.4->discord.py) (2.8)
--- Logging error ---
Traceback (most recent call last):
  File "/usr/local/lib/python3.9/dist-packages/pip/_internal/utils/logging.py", line 177, in emit
    self.console.print(renderable, overflow="ignore", crop=False, style=style)
  File "/usr/local/lib/python3.9/dist-packages/pip/_vendor/rich/console.py", line 1673, in print
    extend(render(renderable, render_options))
  File "/usr/local/lib/python3.9/dist-packages/pip/_vendor/rich/console.py", line 1305, in render
    for render_output in iter_render:
  File "/usr/local/lib/python3.9/dist-packages/pip/_internal/utils/logging.py", line 134, in __rich_console__
    for line in lines:
  File "/usr/local/lib/python3.9/dist-packages/pip/_vendor/rich/segment.py", line 249, in split_lines
    for segment in segments:
  File "/usr/local/lib/python3.9/dist-packages/pip/_vendor/rich/console.py", line 1283, in render
    renderable = rich_cast(renderable)
  File "/usr/local/lib/python3.9/dist-packages/pip/_vendor/rich/protocol.py", line 36, in rich_cast
    renderable = cast_method()
  File "/usr/local/lib/python3.9/dist-packages/pip/_internal/self_outdated_check.py", line 130, in __rich__
    pip_cmd = get_best_invocation_for_this_pip()
  File "/usr/local/lib/python3.9/dist-packages/pip/_internal/utils/entrypoints.py", line 58, in get_best_invocation_for_this_pip
    if found_executable and os.path.samefile(
  File "/usr/lib/python3.9/genericpath.py", line 101, in samefile
    s2 = os.stat(f2)
FileNotFoundError: [Errno 2] No such file or directory: '/usr/bin/pip3.9'
Call stack:
  File "/usr/lib/python3.9/runpy.py", line 197, in _run_module_as_main
    return _run_code(code, main_globals, None,
  File "/usr/lib/python3.9/runpy.py", line 87, in _run_code
    exec(code, run_globals)
  File "/usr/local/lib/python3.9/dist-packages/pip/__main__.py", line 31, in <module>
    sys.exit(_main())
  File "/usr/local/lib/python3.9/dist-packages/pip/_internal/cli/main.py", line 70, in main
    return command.main(cmd_args)
  File "/usr/local/lib/python3.9/dist-packages/pip/_internal/cli/base_command.py", line 101, in main
    return self._main(args)
  File "/usr/local/lib/python3.9/dist-packages/pip/_internal/cli/base_command.py", line 223, in _main
    self.handle_pip_version_check(options)
  File "/usr/local/lib/python3.9/dist-packages/pip/_internal/cli/req_command.py", line 190, in handle_pip_version_check
    pip_self_version_check(session, options)
  File "/usr/local/lib/python3.9/dist-packages/pip/_internal/self_outdated_check.py", line 236, in pip_self_version_check
    logger.warning("[present-rich] %s", upgrade_prompt)
  File "/usr/lib/python3.9/logging/__init__.py", line 1458, in warning
    self._log(WARNING, msg, args, **kwargs)
  File "/usr/lib/python3.9/logging/__init__.py", line 1589, in _log
    self.handle(record)
  File "/usr/lib/python3.9/logging/__init__.py", line 1599, in handle
    self.callHandlers(record)
  File "/usr/lib/python3.9/logging/__init__.py", line 1661, in callHandlers
    hdlr.handle(record)
  File "/usr/lib/python3.9/logging/__init__.py", line 952, in handle
    self.emit(record)
  File "/usr/local/lib/python3.9/dist-packages/pip/_internal/utils/logging.py", line 179, in emit
    self.handleError(record)
Message: '[present-rich] %s'
Arguments: (UpgradePrompt(old='22.2.2', new='23.0'),)
Defaulting to user installation because normal site-packages is not writeable
Requirement already satisfied: python-dotenv in ./.local/lib/python3.9/site-packages (0.21.1)
--- Logging error ---
Traceback (most recent call last):
  File "/usr/local/lib/python3.9/dist-packages/pip/_internal/utils/logging.py", line 177, in emit
    self.console.print(renderable, overflow="ignore", crop=False, style=style)
  File "/usr/local/lib/python3.9/dist-packages/pip/_vendor/rich/console.py", line 1673, in print
    extend(render(renderable, render_options))
  File "/usr/local/lib/python3.9/dist-packages/pip/_vendor/rich/console.py", line 1305, in render
    for render_output in iter_render:
  File "/usr/local/lib/python3.9/dist-packages/pip/_internal/utils/logging.py", line 134, in __rich_console__
    for line in lines:
  File "/usr/local/lib/python3.9/dist-packages/pip/_vendor/rich/segment.py", line 249, in split_lines
    for segment in segments:
  File "/usr/local/lib/python3.9/dist-packages/pip/_vendor/rich/console.py", line 1283, in render
    renderable = rich_cast(renderable)
  File "/usr/local/lib/python3.9/dist-packages/pip/_vendor/rich/protocol.py", line 36, in rich_cast
    renderable = cast_method()
  File "/usr/local/lib/python3.9/dist-packages/pip/_internal/self_outdated_check.py", line 130, in __rich__
    pip_cmd = get_best_invocation_for_this_pip()
  File "/usr/local/lib/python3.9/dist-packages/pip/_internal/utils/entrypoints.py", line 58, in get_best_invocation_for_this_pip
    if found_executable and os.path.samefile(
  File "/usr/lib/python3.9/genericpath.py", line 101, in samefile
    s2 = os.stat(f2)
FileNotFoundError: [Errno 2] No such file or directory: '/usr/bin/pip3.9'
Call stack:
  File "/usr/lib/python3.9/runpy.py", line 197, in _run_module_as_main
    return _run_code(code, main_globals, None,
  File "/usr/lib/python3.9/runpy.py", line 87, in _run_code
    exec(code, run_globals)
  File "/usr/local/lib/python3.9/dist-packages/pip/__main__.py", line 31, in <module>
    sys.exit(_main())
  File "/usr/local/lib/python3.9/dist-packages/pip/_internal/cli/main.py", line 70, in main
    return command.main(cmd_args)
  File "/usr/local/lib/python3.9/dist-packages/pip/_internal/cli/base_command.py", line 101, in main
    return self._main(args)
  File "/usr/local/lib/python3.9/dist-packages/pip/_internal/cli/base_command.py", line 223, in _main
    self.handle_pip_version_check(options)
  File "/usr/local/lib/python3.9/dist-packages/pip/_internal/cli/req_command.py", line 190, in handle_pip_version_check
    pip_self_version_check(session, options)
  File "/usr/local/lib/python3.9/dist-packages/pip/_internal/self_outdated_check.py", line 236, in pip_self_version_check
    logger.warning("[present-rich] %s", upgrade_prompt)
  File "/usr/lib/python3.9/logging/__init__.py", line 1458, in warning
    self._log(WARNING, msg, args, **kwargs)
  File "/usr/lib/python3.9/logging/__init__.py", line 1589, in _log
    self.handle(record)
  File "/usr/lib/python3.9/logging/__init__.py", line 1599, in handle
    self.callHandlers(record)
  File "/usr/lib/python3.9/logging/__init__.py", line 1661, in callHandlers
    hdlr.handle(record)
  File "/usr/lib/python3.9/logging/__init__.py", line 952, in handle
    self.emit(record)
  File "/usr/local/lib/python3.9/dist-packages/pip/_internal/utils/logging.py", line 179, in emit
    self.handleError(record)
Message: '[present-rich] %s'
Arguments: (UpgradePrompt(old='22.2.2', new='23.0'),)
[2023-02-05 19:05:03] [INFO    ] discord.client: logging in using static token
[2023-02-05 19:05:04] [INFO    ] discord.gateway: Shard ID None has connected to Gateway (Session ID: bee69a8d7dfd912d960d848d28cb5c94).
Logged on as Alibis#0251
Judge checker compare: 3ftAspyn#2845
 vs 3ftAspyn#2845

[2023-02-05 19:05:50] [ERROR   ] discord.client: Ignoring exception in on_message
Traceback (most recent call last):
  File "/home/minecraft/multicraft/servers/server439821/.local/lib/python3.9/site-packages/discord/client.py", line 409, in _run_event
    await coro(*args, **kwargs)
  File "/home/minecraft/multicraft/servers/server439821/Alibis/alibi_bot.py", line 313, in on_message
    n_user = converter.convert(n_player)
TypeError: convert() missing 1 required positional argument: 'argument'
