Defaulting to user installation because normal site-packages is not writeable
Requirement already satisfied: discord.py in ./.local/lib/python3.9/site-packages (2.1.0)
Requirement already satisfied: aiohttp<4,>=3.7.4 in ./.local/lib/python3.9/site-packages (from discord.py) (3.8.3)
Requirement already satisfied: aiosignal>=1.1.2 in ./.local/lib/python3.9/site-packages (from aiohttp<4,>=3.7.4->discord.py) (1.3.1)
Requirement already satisfied: charset-normalizer<3.0,>=2.0 in ./.local/lib/python3.9/site-packages (from aiohttp<4,>=3.7.4->discord.py) (2.1.1)
Requirement already satisfied: multidict<7.0,>=4.5 in ./.local/lib/python3.9/site-packages (from aiohttp<4,>=3.7.4->discord.py) (6.0.4)
Requirement already satisfied: frozenlist>=1.1.1 in ./.local/lib/python3.9/site-packages (from aiohttp<4,>=3.7.4->discord.py) (1.3.3)
Requirement already satisfied: async-timeout<5.0,>=4.0.0a3 in ./.local/lib/python3.9/site-packages (from aiohttp<4,>=3.7.4->discord.py) (4.0.2)
Requirement already satisfied: yarl<2.0,>=1.0 in ./.local/lib/python3.9/site-packages (from aiohttp<4,>=3.7.4->discord.py) (1.8.2)
Requirement already satisfied: attrs>=17.3.0 in ./.local/lib/python3.9/site-packages (from aiohttp<4,>=3.7.4->discord.py) (22.2.0)
Requirement already satisfied: idna>=2.0 in /usr/lib/python3/dist-packages (from yarl<2.0,>=1.0->aiohttp<4,>=3.7.4->discord.py) (2.8)
--- Logging error ---
Traceback (most recent call last):
  File "/usr/local/lib/python3.9/dist-packages/pip/_internal/utils/logging.py", line 177, in emit
    self.console.print(renderable, overflow="ignore", crop=False, style=style)
  File "/usr/local/lib/python3.9/dist-packages/pip/_vendor/rich/console.py", line 1673, in print
    extend(render(renderable, render_options))
  File "/usr/local/lib/python3.9/dist-packages/pip/_vendor/rich/console.py", line 1305, in render
    for render_output in iter_render:
  File "/usr/local/lib/python3.9/dist-packages/pip/_internal/utils/logging.py", line 134, in __rich_console__
    for line in lines:
  File "/usr/local/lib/python3.9/dist-packages/pip/_vendor/rich/segment.py", line 249, in split_lines
    for segment in segments:
  File "/usr/local/lib/python3.9/dist-packages/pip/_vendor/rich/console.py", line 1283, in render
    renderable = rich_cast(renderable)
  File "/usr/local/lib/python3.9/dist-packages/pip/_vendor/rich/protocol.py", line 36, in rich_cast
    renderable = cast_method()
  File "/usr/local/lib/python3.9/dist-packages/pip/_internal/self_outdated_check.py", line 130, in __rich__
    pip_cmd = get_best_invocation_for_this_pip()
  File "/usr/local/lib/python3.9/dist-packages/pip/_internal/utils/entrypoints.py", line 58, in get_best_invocation_for_this_pip
    if found_executable and os.path.samefile(
  File "/usr/lib/python3.9/genericpath.py", line 101, in samefile
    s2 = os.stat(f2)
FileNotFoundError: [Errno 2] No such file or directory: '/usr/bin/pip3.9'
Call stack:
  File "/usr/lib/python3.9/runpy.py", line 197, in _run_module_as_main
    return _run_code(code, main_globals, None,
  File "/usr/lib/python3.9/runpy.py", line 87, in _run_code
    exec(code, run_globals)
  File "/usr/local/lib/python3.9/dist-packages/pip/__main__.py", line 31, in <module>
    sys.exit(_main())
  File "/usr/local/lib/python3.9/dist-packages/pip/_internal/cli/main.py", line 70, in main
    return command.main(cmd_args)
  File "/usr/local/lib/python3.9/dist-packages/pip/_internal/cli/base_command.py", line 101, in main
    return self._main(args)
  File "/usr/local/lib/python3.9/dist-packages/pip/_internal/cli/base_command.py", line 223, in _main
    self.handle_pip_version_check(options)
  File "/usr/local/lib/python3.9/dist-packages/pip/_internal/cli/req_command.py", line 190, in handle_pip_version_check
    pip_self_version_check(session, options)
  File "/usr/local/lib/python3.9/dist-packages/pip/_internal/self_outdated_check.py", line 236, in pip_self_version_check
    logger.warning("[present-rich] %s", upgrade_prompt)
  File "/usr/lib/python3.9/logging/__init__.py", line 1458, in warning
    self._log(WARNING, msg, args, **kwargs)
  File "/usr/lib/python3.9/logging/__init__.py", line 1589, in _log
    self.handle(record)
  File "/usr/lib/python3.9/logging/__init__.py", line 1599, in handle
    self.callHandlers(record)
  File "/usr/lib/python3.9/logging/__init__.py", line 1661, in callHandlers
    hdlr.handle(record)
  File "/usr/lib/python3.9/logging/__init__.py", line 952, in handle
    self.emit(record)
  File "/usr/local/lib/python3.9/dist-packages/pip/_internal/utils/logging.py", line 179, in emit
    self.handleError(record)
Message: '[present-rich] %s'
Arguments: (UpgradePrompt(old='22.2.2', new='23.0'),)
Defaulting to user installation because normal site-packages is not writeable
Requirement already satisfied: python-dotenv in ./.local/lib/python3.9/site-packages (0.21.1)
--- Logging error ---
Traceback (most recent call last):
  File "/usr/local/lib/python3.9/dist-packages/pip/_internal/utils/logging.py", line 177, in emit
    self.console.print(renderable, overflow="ignore", crop=False, style=style)
  File "/usr/local/lib/python3.9/dist-packages/pip/_vendor/rich/console.py", line 1673, in print
    extend(render(renderable, render_options))
  File "/usr/local/lib/python3.9/dist-packages/pip/_vendor/rich/console.py", line 1305, in render
    for render_output in iter_render:
  File "/usr/local/lib/python3.9/dist-packages/pip/_internal/utils/logging.py", line 134, in __rich_console__
    for line in lines:
  File "/usr/local/lib/python3.9/dist-packages/pip/_vendor/rich/segment.py", line 249, in split_lines
    for segment in segments:
  File "/usr/local/lib/python3.9/dist-packages/pip/_vendor/rich/console.py", line 1283, in render
    renderable = rich_cast(renderable)
  File "/usr/local/lib/python3.9/dist-packages/pip/_vendor/rich/protocol.py", line 36, in rich_cast
    renderable = cast_method()
  File "/usr/local/lib/python3.9/dist-packages/pip/_internal/self_outdated_check.py", line 130, in __rich__
    pip_cmd = get_best_invocation_for_this_pip()
  File "/usr/local/lib/python3.9/dist-packages/pip/_internal/utils/entrypoints.py", line 58, in get_best_invocation_for_this_pip
    if found_executable and os.path.samefile(
  File "/usr/lib/python3.9/genericpath.py", line 101, in samefile
    s2 = os.stat(f2)
FileNotFoundError: [Errno 2] No such file or directory: '/usr/bin/pip3.9'
Call stack:
  File "/usr/lib/python3.9/runpy.py", line 197, in _run_module_as_main
    return _run_code(code, main_globals, None,
  File "/usr/lib/python3.9/runpy.py", line 87, in _run_code
    exec(code, run_globals)
  File "/usr/local/lib/python3.9/dist-packages/pip/__main__.py", line 31, in <module>
    sys.exit(_main())
  File "/usr/local/lib/python3.9/dist-packages/pip/_internal/cli/main.py", line 70, in main
    return command.main(cmd_args)
  File "/usr/local/lib/python3.9/dist-packages/pip/_internal/cli/base_command.py", line 101, in main
    return self._main(args)
  File "/usr/local/lib/python3.9/dist-packages/pip/_internal/cli/base_command.py", line 223, in _main
    self.handle_pip_version_check(options)
  File "/usr/local/lib/python3.9/dist-packages/pip/_internal/cli/req_command.py", line 190, in handle_pip_version_check
    pip_self_version_check(session, options)
  File "/usr/local/lib/python3.9/dist-packages/pip/_internal/self_outdated_check.py", line 236, in pip_self_version_check
    logger.warning("[present-rich] %s", upgrade_prompt)
  File "/usr/lib/python3.9/logging/__init__.py", line 1458, in warning
    self._log(WARNING, msg, args, **kwargs)
  File "/usr/lib/python3.9/logging/__init__.py", line 1589, in _log
    self.handle(record)
  File "/usr/lib/python3.9/logging/__init__.py", line 1599, in handle
    self.callHandlers(record)
  File "/usr/lib/python3.9/logging/__init__.py", line 1661, in callHandlers
    hdlr.handle(record)
  File "/usr/lib/python3.9/logging/__init__.py", line 952, in handle
    self.emit(record)
  File "/usr/local/lib/python3.9/dist-packages/pip/_internal/utils/logging.py", line 179, in emit
    self.handleError(record)
Message: '[present-rich] %s'
Arguments: (UpgradePrompt(old='22.2.2', new='23.0'),)
[Loader]Loading 2 files
[Loader]Opening file ./Alibis/alibi_bot.py
[Loader]Opening file ./Discablo/discablo_bot.py
[2023-02-11 00:45:46] [INFO    ] discord.client: logging in using static token
[2023-02-11 00:45:46] [INFO    ] discord.client: logging in using static token
[2023-02-11 00:45:47] [INFO    ] discord.gateway: Shard ID None has connected to Gateway (Session ID: af009b42f7297856cd7197c27a3f575e).
[2023-02-11 00:45:47] [INFO    ] discord.gateway: Shard ID None has connected to Gateway (Session ID: 77fd02ef02f7408c2a9f65e0040a6372).
Logged on as Moriarti#0251
Logged on as Discablo#6352
[2023-02-11 00:46:00] [ERROR   ] discord.client: Ignoring exception in on_message
Traceback (most recent call last):
  File "/home/minecraft/multicraft/servers/server439821/.local/lib/python3.9/site-packages/discord/client.py", line 409, in _run_event
    await coro(*args, **kwargs)
  File "/home/minecraft/multicraft/servers/server439821/./Discablo/discablo_bot.py", line 213, in on_message
    await msg.add_reaction('Button: Yes')
  File "/home/minecraft/multicraft/servers/server439821/.local/lib/python3.9/site-packages/discord/message.py", line 1060, in add_reaction
    await self._state.http.add_reaction(self.channel.id, self.id, emoji)
  File "/home/minecraft/multicraft/servers/server439821/.local/lib/python3.9/site-packages/discord/http.py", line 744, in request
    raise HTTPException(response, data)
discord.errors.HTTPException: 400 Bad Request (error code: 50035): Invalid Form Body
In emoji_id: Value " Yes" is not snowflake.
[2023-02-11 02:02:55] [INFO    ] discord.gateway: Shard ID None has successfully RESUMED session af009b42f7297856cd7197c27a3f575e.
[2023-02-11 02:33:11] [INFO    ] discord.gateway: Shard ID None has successfully RESUMED session af009b42f7297856cd7197c27a3f575e.
[2023-02-11 03:00:14] [INFO    ] discord.gateway: Shard ID None has successfully RESUMED session 77fd02ef02f7408c2a9f65e0040a6372.
[2023-02-11 04:47:01] [INFO    ] discord.gateway: Shard ID None has successfully RESUMED session 77fd02ef02f7408c2a9f65e0040a6372.
[2023-02-11 06:25:54] [INFO    ] discord.gateway: Shard ID None has successfully RESUMED session 77fd02ef02f7408c2a9f65e0040a6372.
[2023-02-11 06:26:21] [INFO    ] discord.gateway: Shard ID None has successfully RESUMED session af009b42f7297856cd7197c27a3f575e.
[2023-02-11 08:02:52] [INFO    ] discord.gateway: Shard ID None has successfully RESUMED session 77fd02ef02f7408c2a9f65e0040a6372.
[2023-02-11 10:07:26] [INFO    ] discord.gateway: Shard ID None has successfully RESUMED session 77fd02ef02f7408c2a9f65e0040a6372.
[2023-02-11 10:22:05] [INFO    ] discord.gateway: Shard ID None has successfully RESUMED session af009b42f7297856cd7197c27a3f575e.
[2023-02-11 11:36:38] [INFO    ] discord.gateway: Shard ID None has successfully RESUMED session 77fd02ef02f7408c2a9f65e0040a6372.
[2023-02-11 12:50:44] [INFO    ] discord.gateway: Shard ID None has successfully RESUMED session af009b42f7297856cd7197c27a3f575e.
[2023-02-11 13:35:29] [INFO    ] discord.gateway: Shard ID None has successfully RESUMED session 77fd02ef02f7408c2a9f65e0040a6372.
[2023-02-11 14:16:10] [INFO    ] discord.gateway: Shard ID None has successfully RESUMED session 77fd02ef02f7408c2a9f65e0040a6372.
[2023-02-11 14:52:42] [INFO    ] discord.gateway: Shard ID None has successfully RESUMED session af009b42f7297856cd7197c27a3f575e.
[2023-02-11 15:29:44] [INFO    ] discord.gateway: Shard ID None has successfully RESUMED session af009b42f7297856cd7197c27a3f575e.
[2023-02-11 16:43:35] [INFO    ] discord.gateway: Shard ID None has successfully RESUMED session 77fd02ef02f7408c2a9f65e0040a6372.
[2023-02-11 18:21:26] [INFO    ] discord.gateway: Shard ID None has successfully RESUMED session af009b42f7297856cd7197c27a3f575e.
[2023-02-11 18:40:32] [INFO    ] discord.gateway: Shard ID None has successfully RESUMED session 77fd02ef02f7408c2a9f65e0040a6372.
[2023-02-11 18:59:00] [INFO    ] discord.gateway: Shard ID None has successfully RESUMED session 77fd02ef02f7408c2a9f65e0040a6372.
[2023-02-11 20:46:51] [INFO    ] discord.gateway: Shard ID None has successfully RESUMED session af009b42f7297856cd7197c27a3f575e.
[2023-02-11 20:52:12] [INFO    ] discord.gateway: Shard ID None has successfully RESUMED session 77fd02ef02f7408c2a9f65e0040a6372.
[2023-02-11 21:25:47] [INFO    ] discord.gateway: Shard ID None has successfully RESUMED session af009b42f7297856cd7197c27a3f575e.
[2023-02-11 22:46:13] [INFO    ] discord.gateway: Shard ID None has successfully RESUMED session 77fd02ef02f7408c2a9f65e0040a6372.
[2023-02-11 23:49:45] [INFO    ] discord.gateway: Shard ID None has successfully RESUMED session af009b42f7297856cd7197c27a3f575e.
[2023-02-12 00:18:18] [INFO    ] discord.gateway: Shard ID None has successfully RESUMED session af009b42f7297856cd7197c27a3f575e.
[2023-02-12 01:57:25] [INFO    ] discord.gateway: Shard ID None has successfully RESUMED session af009b42f7297856cd7197c27a3f575e.
[2023-02-12 02:02:55] [INFO    ] discord.gateway: Shard ID None has successfully RESUMED session 77fd02ef02f7408c2a9f65e0040a6372.
[2023-02-12 03:38:02] [INFO    ] discord.gateway: Shard ID None has successfully RESUMED session af009b42f7297856cd7197c27a3f575e.
[2023-02-12 04:37:23] [INFO    ] discord.gateway: Shard ID None has successfully RESUMED session 77fd02ef02f7408c2a9f65e0040a6372.
[2023-02-12 04:59:43] [INFO    ] discord.gateway: Shard ID None has successfully RESUMED session 77fd02ef02f7408c2a9f65e0040a6372.
[2023-02-12 05:08:46] [ERROR   ] discord.client: Ignoring exception in on_message
Traceback (most recent call last):
  File "/home/minecraft/multicraft/servers/server439821/.local/lib/python3.9/site-packages/discord/client.py", line 409, in _run_event
    await coro(*args, **kwargs)
  File "/home/minecraft/multicraft/servers/server439821/./Alibis/alibi_bot.py", line 405, in on_message
    n_user = await converter.convert(message.author, n_player.rstrip())
AttributeError: 'bool' object has no attribute 'rstrip'
